<?xml version="1.0" ?>
<robot name="usf_robot" xmlns:xacro="http://www.ros.org/wiki/xacro">

<xacro:include filename="$(find usf_robot_description)/urdf/materials.xacro" />
<xacro:include filename="$(find usf_robot_description)/urdf/usf_robot.trans" />
<xacro:include filename="$(find usf_robot_description)/urdf/usf_robot.gazebo" />
<link name="base_link">
  <inertial>
    <origin xyz="4.095840186019689e-05 -0.00047837113585616297 0.030465846604467023" rpy="0 0 0"/>
    <mass value="6.2514798322801415"/>
    <inertia ixx="0.01073" iyy="0.010393" izz="0.014172" ixy="-0.0" iyz="8e-06" ixz="0.0"/>
  </inertial>
  <visual>
    <origin xyz="0 0 0" rpy="0 0 0"/>
    <geometry>
      <mesh filename="file://$(find usf_robot_description)/meshes/base_link.stl" scale="0.001 0.001 0.001"/>
    </geometry>
    <material name="silver"/>
  </visual>
  <collision>
    <origin xyz="0 0 0" rpy="0 0 0"/>
    <geometry>
      <mesh filename="file://$(find usf_robot_description)/meshes/base_link.stl" scale="0.001 0.001 0.001"/>
    </geometry>
  </collision>
</link>

<link name="link0_1">
  <inertial>
    <origin xyz="-2.716259298227874e-06 -0.0010380049259447563 0.024075797292657686" rpy="0 0 0"/>
    <mass value="1.1929271090807336"/>
    <inertia ixx="0.001533" iyy="0.001298" izz="0.000904" ixy="1e-06" iyz="3.9e-05" ixz="-0.0"/>
  </inertial>
  <visual>
    <origin xyz="0.0002 0.000356 -0.07854" rpy="0 0 0"/>
    <geometry>
      <mesh filename="file://$(find usf_robot_description)/meshes/link0_1.stl" scale="0.001 0.001 0.001"/>
    </geometry>
    <material name="silver"/>
  </visual>
  <collision>
    <origin xyz="0.0002 0.000356 -0.07854" rpy="0 0 0"/>
    <geometry>
      <mesh filename="file://$(find usf_robot_description)/meshes/link0_1.stl" scale="0.001 0.001 0.001"/>
    </geometry>
  </collision>
</link>

<link name="link1_1">
  <inertial>
    <origin xyz="-0.1802469603530418 0.20467584818746778 -0.31872975492036304" rpy="0 0 0"/>
    <mass value="0.19172228733298213"/>
    <inertia ixx="0.000679" iyy="0.000532" izz="0.000173" ixy="0.0" iyz="1.7e-05" ixz="-1e-06"/>
  </inertial>
  <visual>
    <origin xyz="-0.180211 0.205134 -0.529867" rpy="0 0 0"/>
    <geometry>
      <mesh filename="file://$(find usf_robot_description)/meshes/link1_1.stl" scale="0.001 0.001 0.001"/>
    </geometry>
    <material name="silver"/>
  </visual>
  <collision>
    <origin xyz="-0.180211 0.205134 -0.529867" rpy="0 0 0"/>
    <geometry>
      <mesh filename="file://$(find usf_robot_description)/meshes/link1_1.stl" scale="0.001 0.001 0.001"/>
    </geometry>
  </collision>
</link>

<link name="link2_1">
  <inertial>
    <origin xyz="-0.0008459448150377875 0.03487723194290493 0.05901407198161318" rpy="0 0 0"/>
    <mass value="0.9310977870000888"/>
    <inertia ixx="0.002972" iyy="0.002261" izz="0.000867" ixy="-0.0" iyz="-2e-06" ixz="1e-05"/>
  </inertial>
  <visual>
    <origin xyz="-0.000411 0.034567 -0.272461" rpy="0 0 0"/>
    <geometry>
      <mesh filename="file://$(find usf_robot_description)/meshes/link2_1.stl" scale="0.001 0.001 0.001"/>
    </geometry>
    <material name="silver"/>
  </visual>
  <collision>
    <origin xyz="-0.000411 0.034567 -0.272461" rpy="0 0 0"/>
    <geometry>
      <mesh filename="file://$(find usf_robot_description)/meshes/link2_1.stl" scale="0.001 0.001 0.001"/>
    </geometry>
  </collision>
</link>

<link name="wrist_1">
  <inertial>
    <origin xyz="-0.0005413092492828724 0.0012694599894110235 0.01735230955560413" rpy="0 0 0"/>
    <mass value="0.27580026748282094"/>
    <inertia ixx="4.6e-05" iyy="0.000102" izz="9.7e-05" ixy="1e-06" iyz="-3e-06" ixz="1e-06"/>
  </inertial>
  <visual>
    <origin xyz="0.009156 -6.5e-05 -0.40079" rpy="0 0 0"/>
    <geometry>
      <mesh filename="file://$(find usf_robot_description)/meshes/wrist_1.stl" scale="0.001 0.001 0.001"/>
    </geometry>
    <material name="silver"/>
  </visual>
  <collision>
    <origin xyz="0.009156 -6.5e-05 -0.40079" rpy="0 0 0"/>
    <geometry>
      <mesh filename="file://$(find usf_robot_description)/meshes/wrist_1.stl" scale="0.001 0.001 0.001"/>
    </geometry>
  </collision>
</link>

<link name="claw0_1">
  <inertial>
    <origin xyz="0.029746498963837457 -0.015181296968975203 0.0037018851488843096" rpy="0 0 0"/>
    <mass value="0.06042467247708934"/>
    <inertia ixx="1.9e-05" iyy="1.7e-05" izz="2.8e-05" ixy="6e-06" iyz="1e-06" ixz="-4e-06"/>
  </inertial>
  <visual>
    <origin xyz="0.001497 -0.024737 -0.429729" rpy="0 0 0"/>
    <geometry>
      <mesh filename="file://$(find usf_robot_description)/meshes/claw0_1.stl" scale="0.001 0.001 0.001"/>
    </geometry>
    <material name="silver"/>
  </visual>
  <collision>
    <origin xyz="0.001497 -0.024737 -0.429729" rpy="0 0 0"/>
    <geometry>
      <mesh filename="file://$(find usf_robot_description)/meshes/claw0_1.stl" scale="0.001 0.001 0.001"/>
    </geometry>
  </collision>
</link>

<link name="claw1_1">
  <inertial>
    <origin xyz="-0.024769673493672317 -0.006850523309569284 0.0028712566060522526" rpy="0 0 0"/>
    <mass value="0.07705542391594017"/>
    <inertia ixx="2.2e-05" iyy="3.1e-05" izz="4.3e-05" ixy="-1e-05" iyz="1e-06" ixz="5e-06"/>
  </inertial>
  <visual>
    <origin xyz="0.017623 -0.016646 -0.42967" rpy="0 0 0"/>
    <geometry>
      <mesh filename="file://$(find usf_robot_description)/meshes/claw1_1.stl" scale="0.001 0.001 0.001"/>
    </geometry>
    <material name="silver"/>
  </visual>
  <collision>
    <origin xyz="0.017623 -0.016646 -0.42967" rpy="0 0 0"/>
    <geometry>
      <mesh filename="file://$(find usf_robot_description)/meshes/claw1_1.stl" scale="0.001 0.001 0.001"/>
    </geometry>
  </collision>
</link>

<joint name="link0_to_base_link" type="revolute">
  <origin xyz="-0.0002 -0.000356 0.07854" rpy="0 0 0"/>
  <parent link="base_link"/>
  <child link="link0_1"/>
  <axis xyz="-0.0 0.0 1.0"/>
  <limit upper="4.712389" lower="0.0" effort="100" velocity="100"/>
</joint>

<joint name="link1_to_link0" type="revolute">
  <origin xyz="0.180411 -0.204778 0.451327" rpy="0 0 0"/>
  <parent link="link0_1"/>
  <child link="link1_1"/>
  <axis xyz="0.0 -1.0 -0.0"/>
  <limit upper="1.570796" lower="-1.570796" effort="100" velocity="100"/>
</joint>

<joint name="link2_to_link1" type="revolute">
  <origin xyz="-0.1798 0.170567 -0.257406" rpy="0 0 0"/>
  <parent link="link1_1"/>
  <child link="link2_1"/>
  <axis xyz="-0.0 -1.0 -0.0"/>
  <limit upper="1.570796" lower="-1.570796" effort="100" velocity="100"/>
</joint>

<joint name="wrist_to_link2" type="revolute">
  <origin xyz="-0.009567 0.034632 0.128329" rpy="0 0 0"/>
  <parent link="link2_1"/>
  <child link="wrist_1"/>
  <axis xyz="-0.0 -0.0 1.0"/>
  <limit upper="4.712389" lower="0.0" effort="100" velocity="100"/>
</joint>

<joint name="claw0_to_wrist" type="revolute">
  <origin xyz="0.007659 0.024672 0.028939" rpy="0 0 0"/>
  <parent link="wrist_1"/>
  <child link="claw0_1"/>
  <axis xyz="0.0 -1.0 -0.0"/>
  <limit upper="1.134464" lower="-0.261799" effort="100" velocity="100"/>
</joint>

<joint name="claw1_to_wrist" type="revolute">
  <origin xyz="-0.008467 0.016581 0.02888" rpy="0 0 0"/>
  <parent link="wrist_1"/>
  <child link="claw1_1"/>
  <axis xyz="-0.0 1.0 0.0"/>
  <limit upper="1.134464" lower="-0.261799" effort="100" velocity="100"/>
</joint>

</robot>
