<?xml version="1.0" ?>
<robot name="usf_robot" xmlns:xacro="http://www.ros.org/wiki/xacro">

<xacro:include filename="$(find usf_robot_description)/urdf/materials.xacro" />
<xacro:include filename="$(find usf_robot_description)/urdf/usf_robot.trans" />
<xacro:include filename="$(find usf_robot_description)/urdf/usf_robot.gazebo" />
<link name="base_link">
  <inertial>
    <origin xyz="0.0004913446203376246 -0.00044763170485451453 0.03115650951572913" rpy="0 0 0"/>
    <mass value="6.46115675320504"/>
    <inertia ixx="0.010854" iyy="0.010576" izz="0.014247" ixy="-3e-06" iyz="3e-06" ixz="-6.1e-05"/>
  </inertial>
  <visual>
    <origin xyz="0 0 0" rpy="0 0 0"/>
    <geometry>
      <mesh filename="file://$(find usf_robot_description)/meshes/base_link.stl" scale="0.001 0.001 0.001"/>
    </geometry>
    <material name="silver"/>
  </visual>
  <collision>
    <origin xyz="0 0 0" rpy="0 0 0"/>
    <geometry>
      <mesh filename="file://$(find usf_robot_description)/meshes/base_link.stl" scale="0.001 0.001 0.001"/>
    </geometry>
  </collision>
</link>

<link name="Link_0_1">
  <inertial>
    <origin xyz="-2.5041466755190657e-05 -0.0013096919354106424 0.028411282634595955" rpy="0 0 0"/>
    <mass value="1.0476252776945487"/>
    <inertia ixx="0.001383" iyy="0.001069" izz="0.000729" ixy="1e-06" iyz="3.9e-05" ixz="0.0"/>
  </inertial>
  <visual>
    <origin xyz="-0.001811 -0.000327 -0.077202" rpy="0 0 0"/>
    <geometry>
      <mesh filename="file://$(find usf_robot_description)/meshes/Link_0_1.stl" scale="0.001 0.001 0.001"/>
    </geometry>
    <material name="silver"/>
  </visual>
  <collision>
    <origin xyz="-0.001811 -0.000327 -0.077202" rpy="0 0 0"/>
    <geometry>
      <mesh filename="file://$(find usf_robot_description)/meshes/Link_0_1.stl" scale="0.001 0.001 0.001"/>
    </geometry>
  </collision>
</link>

<link name="Link_1_1">
  <inertial>
    <origin xyz="-0.1821866139138745 0.2037077479782602 -0.31967466757156937" rpy="0 0 0"/>
    <mass value="1.1803686864416578"/>
    <inertia ixx="0.004221" iyy="0.003299" izz="0.001081" ixy="1e-06" iyz="7.4e-05" ixz="-4e-06"/>
  </inertial>
  <visual>
    <origin xyz="-0.184134 0.204669 -0.529391" rpy="0 0 0"/>
    <geometry>
      <mesh filename="file://$(find usf_robot_description)/meshes/Link_1_1.stl" scale="0.001 0.001 0.001"/>
    </geometry>
    <material name="silver"/>
  </visual>
  <collision>
    <origin xyz="-0.184134 0.204669 -0.529391" rpy="0 0 0"/>
    <geometry>
      <mesh filename="file://$(find usf_robot_description)/meshes/Link_1_1.stl" scale="0.001 0.001 0.001"/>
    </geometry>
  </collision>
</link>

<link name="Link_2_1">
  <inertial>
    <origin xyz="-0.0028502190639075322 0.4427242972375212 0.36806986181869167" rpy="0 0 0"/>
    <mass value="0.9310977870000888"/>
    <inertia ixx="0.002972" iyy="0.002261" izz="0.000867" ixy="-0.0" iyz="-2e-06" ixz="1e-05"/>
  </inertial>
  <visual>
    <origin xyz="-0.004319 0.442546 0.036834" rpy="0 0 0"/>
    <geometry>
      <mesh filename="file://$(find usf_robot_description)/meshes/Link_2_1.stl" scale="0.001 0.001 0.001"/>
    </geometry>
    <material name="silver"/>
  </visual>
  <collision>
    <origin xyz="-0.004319 0.442546 0.036834" rpy="0 0 0"/>
    <geometry>
      <mesh filename="file://$(find usf_robot_description)/meshes/Link_2_1.stl" scale="0.001 0.001 0.001"/>
    </geometry>
  </collision>
</link>

<link name="Wrist_Rotation_1">
  <inertial>
    <origin xyz="-0.0005415865300162836 0.0012695252840316611 0.017352099068659532" rpy="0 0 0"/>
    <mass value="0.27580026748282094"/>
    <inertia ixx="4.6e-05" iyy="0.000102" izz="9.7e-05" ixy="1e-06" iyz="-3e-06" ixz="1e-06"/>
  </inertial>
  <visual>
    <origin xyz="0.007252 6.7e-05 -0.400551" rpy="0 0 0"/>
    <geometry>
      <mesh filename="file://$(find usf_robot_description)/meshes/Wrist_Rotation_1.stl" scale="0.001 0.001 0.001"/>
    </geometry>
    <material name="silver"/>
  </visual>
  <collision>
    <origin xyz="0.007252 6.7e-05 -0.400551" rpy="0 0 0"/>
    <geometry>
      <mesh filename="file://$(find usf_robot_description)/meshes/Wrist_Rotation_1.stl" scale="0.001 0.001 0.001"/>
    </geometry>
  </collision>
</link>

<link name="Claw_0_1">
  <inertial>
    <origin xyz="0.029218221148266665 -0.017983231674353804 0.0014626759894252883" rpy="0 0 0"/>
    <mass value="0.06042467247708934"/>
    <inertia ixx="1.9e-05" iyy="1.7e-05" izz="2.8e-05" ixy="6e-06" iyz="1e-06" ixz="-4e-06"/>
  </inertial>
  <visual>
    <origin xyz="-0.000935 -0.025407 -0.431729" rpy="0 0 0"/>
    <geometry>
      <mesh filename="file://$(find usf_robot_description)/meshes/Claw_0_1.stl" scale="0.001 0.001 0.001"/>
    </geometry>
    <material name="silver"/>
  </visual>
  <collision>
    <origin xyz="-0.000935 -0.025407 -0.431729" rpy="0 0 0"/>
    <geometry>
      <mesh filename="file://$(find usf_robot_description)/meshes/Claw_0_1.stl" scale="0.001 0.001 0.001"/>
    </geometry>
  </collision>
</link>

<link name="Claw_1_1">
  <inertial>
    <origin xyz="-0.02476895127812138 -0.006850458014947897 0.0028720449753315558" rpy="0 0 0"/>
    <mass value="0.07705542391594017"/>
    <inertia ixx="2.2e-05" iyy="3.1e-05" izz="4.3e-05" ixy="-1e-05" iyz="1e-06" ixz="5e-06"/>
  </inertial>
  <visual>
    <origin xyz="0.01572 -0.016514 -0.42943" rpy="0 0 0"/>
    <geometry>
      <mesh filename="file://$(find usf_robot_description)/meshes/Claw_1_1.stl" scale="0.001 0.001 0.001"/>
    </geometry>
    <material name="silver"/>
  </visual>
  <collision>
    <origin xyz="0.01572 -0.016514 -0.42943" rpy="0 0 0"/>
    <geometry>
      <mesh filename="file://$(find usf_robot_description)/meshes/Claw_1_1.stl" scale="0.001 0.001 0.001"/>
    </geometry>
  </collision>
</link>

<joint name="link0_to_base_link" type="revolute">
  <origin xyz="0.001811 0.000327 0.077202" rpy="0 0 0"/>
  <parent link="base_link"/>
  <child link="Link_0_1"/>
  <axis xyz="-0.0 0.0 1.0"/>
  <limit upper="4.712389" lower="0.0" effort="100" velocity="100"/>
</joint>

<joint name="link1_to_link0" type="revolute">
  <origin xyz="0.182323 -0.204996 0.452189" rpy="0 0 0"/>
  <parent link="Link_0_1"/>
  <child link="Link_1_1"/>
  <axis xyz="-0.0 -1.0 0.0"/>
  <limit upper="1.570796" lower="-1.570796" effort="100" velocity="100"/>
</joint>

<joint name="link2_to_link1" type="revolute">
  <origin xyz="-0.179815 -0.237877 -0.566225" rpy="0 0 0"/>
  <parent link="Link_1_1"/>
  <child link="Link_2_1"/>
  <axis xyz="-0.0 -1.0 0.0"/>
  <limit upper="1.570796" lower="-1.570796" effort="100" velocity="100"/>
</joint>

<joint name="wrist_to_link2" type="revolute">
  <origin xyz="-0.011571 0.442479 0.437385" rpy="0 0 0"/>
  <parent link="Link_2_1"/>
  <child link="Wrist_Rotation_1"/>
  <axis xyz="-0.0 0.0 1.0"/>
  <limit upper="4.712389" lower="0.0" effort="100" velocity="100"/>
</joint>

<joint name="claw0_to_wrist" type="revolute">
  <origin xyz="0.008187 0.025474 0.031178" rpy="0 0 0"/>
  <parent link="Wrist_Rotation_1"/>
  <child link="Claw_0_1"/>
  <axis xyz="0.0 -1.0 -0.0"/>
  <limit upper="1.047198" lower="0.0" effort="100" velocity="100"/>
</joint>

<joint name="claw1_to_wrist" type="revolute">
  <origin xyz="-0.008468 0.016581 0.028879" rpy="0 0 0"/>
  <parent link="Wrist_Rotation_1"/>
  <child link="Claw_1_1"/>
  <axis xyz="-0.0 1.0 -0.0"/>
  <limit upper="1.047198" lower="0.0" effort="100" velocity="100"/>
</joint>

</robot>
