<?xml version="1.0" ?>
<robot name="usf_robot" xmlns:xacro="http://www.ros.org/wiki/xacro">

<xacro:include filename="$(find usf_robot_description)/urdf/materials.xacro" />
<xacro:include filename="$(find usf_robot_description)/urdf/usf_robot.trans" />
<xacro:include filename="$(find usf_robot_description)/urdf/usf_robot.gazebo" />
<link name="base_link">
  <inertial>
    <origin xyz="-0.00195610987592385 3.213530216617951e-05 0.061248757251813606" rpy="0 0 0"/>
    <mass value="5.924412496829834"/>
    <inertia ixx="0.016063" iyy="0.015454" izz="0.016791" ixy="-5.2e-05" iyz="0.000165" ixz="-0.000371"/>
  </inertial>
  <visual>
    <origin xyz="0 0 0" rpy="0 0 0"/>
    <geometry>
      <mesh filename="file://$(find usf_robot_description)/meshes/base_link.stl" scale="0.001 0.001 0.001"/>
    </geometry>
    <material name="silver"/>
  </visual>
  <collision>
    <origin xyz="0 0 0" rpy="0 0 0"/>
    <geometry>
      <mesh filename="file://$(find usf_robot_description)/meshes/base_link.stl" scale="0.001 0.001 0.001"/>
    </geometry>
  </collision>
</link>

<link name="link0_1">
  <inertial>
    <origin xyz="0.00019728374070177214 -0.0006820049259446852 0.03849479729265773" rpy="0 0 0"/>
    <mass value="1.1929271090807336"/>
    <inertia ixx="0.001533" iyy="0.001298" izz="0.000904" ixy="1e-06" iyz="3.9e-05" ixz="-0.0"/>
  </inertial>
  <visual>
    <origin xyz="0.0004 0.000712 -0.106121" rpy="0 0 0"/>
    <geometry>
      <mesh filename="file://$(find usf_robot_description)/meshes/link0_1.stl" scale="0.001 0.001 0.001"/>
    </geometry>
    <material name="silver"/>
  </visual>
  <collision>
    <origin xyz="0.0004 0.000712 -0.106121" rpy="0 0 0"/>
    <geometry>
      <mesh filename="file://$(find usf_robot_description)/meshes/link0_1.stl" scale="0.001 0.001 0.001"/>
    </geometry>
  </collision>
</link>

<link name="link1_1">
  <inertial>
    <origin xyz="-0.1801747820656201 0.20388991238585638 -0.36201286667631755" rpy="0 0 0"/>
    <mass value="1.1803686864416578"/>
    <inertia ixx="0.004221" iyy="0.003299" izz="0.001081" ixy="1e-06" iyz="7.4e-05" ixz="-4e-06"/>
  </inertial>
  <visual>
    <origin xyz="-0.180211 0.205134 -0.613867" rpy="0 0 0"/>
    <geometry>
      <mesh filename="file://$(find usf_robot_description)/meshes/link1_1.stl" scale="0.001 0.001 0.001"/>
    </geometry>
    <material name="silver"/>
  </visual>
  <collision>
    <origin xyz="-0.180211 0.205134 -0.613867" rpy="0 0 0"/>
    <geometry>
      <mesh filename="file://$(find usf_robot_description)/meshes/link1_1.stl" scale="0.001 0.001 0.001"/>
    </geometry>
  </collision>
</link>

<link name="link2_1">
  <inertial>
    <origin xyz="-0.000938382964558258 0.48436246164511126 0.36835266273068673" rpy="0 0 0"/>
    <mass value="0.9310977870000888"/>
    <inertia ixx="0.002972" iyy="0.002261" izz="0.000867" ixy="-0.0" iyz="-2e-06" ixz="1e-05"/>
  </inertial>
  <visual>
    <origin xyz="-0.000496 0.484967 -0.005021" rpy="0 0 0"/>
    <geometry>
      <mesh filename="file://$(find usf_robot_description)/meshes/link2_1.stl" scale="0.001 0.001 0.001"/>
    </geometry>
    <material name="silver"/>
  </visual>
  <collision>
    <origin xyz="-0.000496 0.484967 -0.005021" rpy="0 0 0"/>
    <geometry>
      <mesh filename="file://$(find usf_robot_description)/meshes/link2_1.stl" scale="0.001 0.001 0.001"/>
    </geometry>
  </collision>
</link>

<link name="wrist_1">
  <inertial>
    <origin xyz="-0.0005417473988033432 0.001269689691617367 0.0173529003046779" rpy="0 0 0"/>
    <mass value="0.27580026748282094"/>
    <inertia ixx="4.6e-05" iyy="0.000102" izz="9.7e-05" ixy="1e-06" iyz="-3e-06" ixz="1e-06"/>
  </inertial>
  <visual>
    <origin xyz="0.009163 0.00085 -0.442688" rpy="0 0 0"/>
    <geometry>
      <mesh filename="file://$(find usf_robot_description)/meshes/wrist_1.stl" scale="0.001 0.001 0.001"/>
    </geometry>
    <material name="silver"/>
  </visual>
  <collision>
    <origin xyz="0.009163 0.00085 -0.442688" rpy="0 0 0"/>
    <geometry>
      <mesh filename="file://$(find usf_robot_description)/meshes/wrist_1.stl" scale="0.001 0.001 0.001"/>
    </geometry>
  </collision>
</link>

<link name="claw0_1">
  <inertial>
    <origin xyz="0.029747060814316988 -0.015181067266768865 0.0037024758979579686" rpy="0 0 0"/>
    <mass value="0.06042467247708934"/>
    <inertia ixx="1.9e-05" iyy="1.7e-05" izz="2.8e-05" ixy="6e-06" iyz="1e-06" ixz="-4e-06"/>
  </inertial>
  <visual>
    <origin xyz="0.001505 -0.023822 -0.471627" rpy="0 0 0"/>
    <geometry>
      <mesh filename="file://$(find usf_robot_description)/meshes/claw0_1.stl" scale="0.001 0.001 0.001"/>
    </geometry>
    <material name="silver"/>
  </visual>
  <collision>
    <origin xyz="0.001505 -0.023822 -0.471627" rpy="0 0 0"/>
    <geometry>
      <mesh filename="file://$(find usf_robot_description)/meshes/claw0_1.stl" scale="0.001 0.001 0.001"/>
    </geometry>
  </collision>
</link>

<link name="claw1_1">
  <inertial>
    <origin xyz="-0.02338711164319279 -0.004770293607362907 -0.04150515264487398" rpy="0 0 0"/>
    <mass value="0.07705542391594017"/>
    <inertia ixx="2.2e-05" iyy="3.1e-05" izz="4.3e-05" ixy="-1e-05" iyz="1e-06" ixz="5e-06"/>
  </inertial>
  <visual>
    <origin xyz="0.019013 -0.015751 -0.515945" rpy="0 0 0"/>
    <geometry>
      <mesh filename="file://$(find usf_robot_description)/meshes/claw1_1.stl" scale="0.001 0.001 0.001"/>
    </geometry>
    <material name="silver"/>
  </visual>
  <collision>
    <origin xyz="0.019013 -0.015751 -0.515945" rpy="0 0 0"/>
    <geometry>
      <mesh filename="file://$(find usf_robot_description)/meshes/claw1_1.stl" scale="0.001 0.001 0.001"/>
    </geometry>
  </collision>
</link>

<joint name="link0_to_base_link" type="revolute">
  <origin xyz="-0.0004 -0.000712 0.106121" rpy="0 0 0"/>
  <parent link="base_link"/>
  <child link="link0_1"/>
  <axis xyz="-0.0 -0.0 1.0"/>
  <limit upper="4.712389" lower="0.0" effort="100" velocity="100"/>
</joint>

<joint name="link1_to_link0" type="revolute">
  <origin xyz="0.180611 -0.204422 0.507746" rpy="0 0 0"/>
  <parent link="link0_1"/>
  <child link="link1_1"/>
  <axis xyz="0.0 -1.0 -0.0"/>
  <limit upper="1.570796" lower="-1.570796" effort="100" velocity="100"/>
</joint>

<joint name="link2_to_link1" type="revolute">
  <origin xyz="-0.179715 -0.279833 -0.608846" rpy="0 0 0"/>
  <parent link="link1_1"/>
  <child link="link2_1"/>
  <axis xyz="0.0 -1.0 -0.0"/>
  <limit upper="1.570796" lower="-1.570796" effort="100" velocity="100"/>
</joint>

<joint name="wrist_to_link2" type="revolute">
  <origin xyz="-0.009659 0.484117 0.437667" rpy="0 0 0"/>
  <parent link="link2_1"/>
  <child link="wrist_1"/>
  <axis xyz="-0.0 -0.0 1.0"/>
  <limit upper="4.712389" lower="0.0" effort="100" velocity="100"/>
</joint>

<joint name="claw0_to_wrist" type="revolute">
  <origin xyz="0.007658 0.024672 0.028939" rpy="0 0 0"/>
  <parent link="wrist_1"/>
  <child link="claw0_1"/>
  <axis xyz="0.0 -1.0 -0.0"/>
  <limit upper="1.134464" lower="-0.261799" effort="100" velocity="100"/>
</joint>

<joint name="claw1_to_wrist" type="revolute">
  <origin xyz="-0.00985 0.016601 0.073257" rpy="0 0 0"/>
  <parent link="wrist_1"/>
  <child link="claw1_1"/>
  <axis xyz="-0.0 1.0 0.0"/>
  <limit upper="1.134464" lower="-0.261799" effort="100" velocity="100"/>
</joint>

</robot>
