<?xml version="1.0" ?>
<robot name="usf_robot" xmlns:xacro="http://www.ros.org/wiki/xacro">

<xacro:include filename="$(find usf_robot_description)/urdf/materials.xacro" />
<xacro:include filename="$(find usf_robot_description)/urdf/usf_robot.trans" />
<xacro:include filename="$(find usf_robot_description)/urdf/usf_robot.gazebo" />
<link name="base_link">
  <inertial>
    <origin xyz="-0.0011969911448842135 -0.00012753859226033372 0.0707642197137742" rpy="0 0 0"/>
    <mass value="7.411814248448438"/>
    <inertia ixx="0.02213" iyy="0.021426" izz="0.021839" ixy="-5.2e-05" iyz="0.000196" ixz="-0.000501"/>
  </inertial>
  <visual>
    <origin xyz="0 0 0" rpy="0 0 0"/>
    <geometry>
      <mesh filename="file://$(find usf_robot_description)/meshes/base_link.stl" scale="0.001 0.001 0.001"/>
    </geometry>
    <material name="silver"/>
  </visual>
  <collision>
    <origin xyz="0 0 0" rpy="0 0 0"/>
    <geometry>
      <mesh filename="file://$(find usf_robot_description)/meshes/base_link.stl" scale="0.001 0.001 0.001"/>
    </geometry>
  </collision>
</link>

<link name="link0_1">
  <inertial>
    <origin xyz="-0.010035059642157892 0.07553135395382185 0.17421827397032785" rpy="0 0 0"/>
    <mass value="0.7933092070470534"/>
    <inertia ixx="0.001018" iyy="0.000756" izz="0.00066" ixy="0.0" iyz="-5e-05" ixz="1e-06"/>
  </inertial>
  <visual>
    <origin xyz="-0.011275 0.073247 0.016017" rpy="0 0 0"/>
    <geometry>
      <mesh filename="file://$(find usf_robot_description)/meshes/link0_1.stl" scale="0.001 0.001 0.001"/>
    </geometry>
    <material name="silver"/>
  </visual>
  <collision>
    <origin xyz="-0.011275 0.073247 0.016017" rpy="0 0 0"/>
    <geometry>
      <mesh filename="file://$(find usf_robot_description)/meshes/link0_1.stl" scale="0.001 0.001 0.001"/>
    </geometry>
  </collision>
</link>

<link name="link1_1">
  <inertial>
    <origin xyz="-0.1817602089462692 0.20008906902487053 -0.39522520140694634" rpy="0 0 0"/>
    <mass value="0.914788434566525"/>
    <inertia ixx="0.003161" iyy="0.002305" izz="0.000997" ixy="0.0" iyz="-7e-05" ixz="-3e-06"/>
  </inertial>
  <visual>
    <origin xyz="-0.183027 0.197349 -0.651732" rpy="0 0 0"/>
    <geometry>
      <mesh filename="file://$(find usf_robot_description)/meshes/link1_1.stl" scale="0.001 0.001 0.001"/>
    </geometry>
    <material name="silver"/>
  </visual>
  <collision>
    <origin xyz="-0.183027 0.197349 -0.651732" rpy="0 0 0"/>
    <geometry>
      <mesh filename="file://$(find usf_robot_description)/meshes/link1_1.stl" scale="0.001 0.001 0.001"/>
    </geometry>
  </collision>
</link>

<link name="link2_1">
  <inertial>
    <origin xyz="-0.0020639216731031303 0.5038970528513304 0.3553073391498673" rpy="0 0 0"/>
    <mass value="0.8509538225045565"/>
    <inertia ixx="0.002727" iyy="0.002026" izz="0.000847" ixy="-0.0" iyz="1.8e-05" ixz="3e-06"/>
  </inertial>
  <visual>
    <origin xyz="-0.003064 0.502322 -0.031464" rpy="0 0 0"/>
    <geometry>
      <mesh filename="file://$(find usf_robot_description)/meshes/link2_1.stl" scale="0.001 0.001 0.001"/>
    </geometry>
    <material name="silver"/>
  </visual>
  <collision>
    <origin xyz="-0.003064 0.502322 -0.031464" rpy="0 0 0"/>
    <geometry>
      <mesh filename="file://$(find usf_robot_description)/meshes/link2_1.stl" scale="0.001 0.001 0.001"/>
    </geometry>
  </collision>
</link>

<link name="wrist_1">
  <inertial>
    <origin xyz="-0.0005299994985208858 0.0008628492364986954 -0.05123809460435541" rpy="0 0 0"/>
    <mass value="0.1957081699891987"/>
    <inertia ixx="2.7e-05" iyy="8.1e-05" izz="8.6e-05" ixy="0.0" iyz="-6e-06" ixz="1e-06"/>
  </inertial>
  <visual>
    <origin xyz="0.005527 -0.002447 -0.518212" rpy="0 0 0"/>
    <geometry>
      <mesh filename="file://$(find usf_robot_description)/meshes/wrist_1.stl" scale="0.001 0.001 0.001"/>
    </geometry>
    <material name="silver"/>
  </visual>
  <collision>
    <origin xyz="0.005527 -0.002447 -0.518212" rpy="0 0 0"/>
    <geometry>
      <mesh filename="file://$(find usf_robot_description)/meshes/wrist_1.stl" scale="0.001 0.001 0.001"/>
    </geometry>
  </collision>
</link>

<link name="claw0_1">
  <inertial>
    <origin xyz="0.029250594772032686 -0.014969999080495884 0.0036447970818933584" rpy="0 0 0"/>
    <mass value="0.057322175974963856"/>
    <inertia ixx="1.9e-05" iyy="1.6e-05" izz="2.7e-05" ixy="6e-06" iyz="1e-06" ixz="-4e-06"/>
  </inertial>
  <visual>
    <origin xyz="-0.001867 -0.025519 -0.481967" rpy="0 0 0"/>
    <geometry>
      <mesh filename="file://$(find usf_robot_description)/meshes/claw0_1.stl" scale="0.001 0.001 0.001"/>
    </geometry>
    <material name="silver"/>
  </visual>
  <collision>
    <origin xyz="-0.001867 -0.025519 -0.481967" rpy="0 0 0"/>
    <geometry>
      <mesh filename="file://$(find usf_robot_description)/meshes/claw0_1.stl" scale="0.001 0.001 0.001"/>
    </geometry>
  </collision>
</link>

<link name="claw1_1">
  <inertial>
    <origin xyz="-0.02500318594534954 -0.003210175370153303 -0.052053266659417674" rpy="0 0 0"/>
    <mass value="0.07764287107086702"/>
    <inertia ixx="2.1e-05" iyy="3.2e-05" izz="4.4e-05" ixy="-1e-05" iyz="1e-06" ixz="5e-06"/>
  </inertial>
  <visual>
    <origin xyz="0.012627 -0.016235 -0.536661" rpy="0 0 0"/>
    <geometry>
      <mesh filename="file://$(find usf_robot_description)/meshes/claw1_1.stl" scale="0.001 0.001 0.001"/>
    </geometry>
    <material name="silver"/>
  </visual>
  <collision>
    <origin xyz="0.012627 -0.016235 -0.536661" rpy="0 0 0"/>
    <geometry>
      <mesh filename="file://$(find usf_robot_description)/meshes/claw1_1.stl" scale="0.001 0.001 0.001"/>
    </geometry>
  </collision>
</link>

<joint name="link0_to_base_link" type="continuous">
  <origin xyz="0.011275 -0.073247 -0.016017" rpy="0 0 0"/>
  <parent link="base_link"/>
  <child link="link0_1"/>
  <axis xyz="0.0 0.0 1.0"/>
</joint>

<joint name="link1_to_link0" type="revolute">
  <origin xyz="0.171752 -0.124102 0.667749" rpy="0 0 0"/>
  <parent link="link0_1"/>
  <child link="link1_1"/>
  <axis xyz="-0.0 -1.0 0.0"/>
  <limit upper="1.570796" lower="-1.570796" effort="100" velocity="100"/>
</joint>

<joint name="link2_to_link1" type="revolute">
  <origin xyz="-0.179963 -0.304973 -0.620268" rpy="0 0 0"/>
  <parent link="link1_1"/>
  <child link="link2_1"/>
  <axis xyz="0.0 -1.0 0.0"/>
  <limit upper="1.570796" lower="-1.570796" effort="100" velocity="100"/>
</joint>

<joint name="wrist_to_link2" type="revolute">
  <origin xyz="-0.008591 0.504769 0.486748" rpy="0 0 0"/>
  <parent link="link2_1"/>
  <child link="wrist_1"/>
  <axis xyz="0.0 -0.0 -1.0"/>
  <limit upper="4.712389" lower="0.0" effort="100" velocity="100"/>
</joint>

<joint name="claw0_to_wrist" type="revolute">
  <origin xyz="0.007394 0.023072 -0.036245" rpy="0 0 0"/>
  <parent link="wrist_1"/>
  <child link="claw0_1"/>
  <axis xyz="0.0 -1.0 0.0"/>
  <limit upper="1.134464" lower="-0.261799" effort="100" velocity="100"/>
</joint>

<joint name="Revolute 6" type="revolute">
  <origin xyz="-0.0071 0.013788 0.018449" rpy="0 0 0"/>
  <parent link="wrist_1"/>
  <child link="claw1_1"/>
  <axis xyz="-0.0 1.0 -0.0"/>
  <limit upper="1.134464" lower="-0.261799" effort="100" velocity="100"/>
</joint>

</robot>
