<?xml version="1.0" ?>
<robot name="usf_robot" xmlns:xacro="http://www.ros.org/wiki/xacro">

<xacro:include filename="$(find usf_robot_description)/urdf/materials.xacro" />
<xacro:include filename="$(find usf_robot_description)/urdf/usf_robot.trans" />
<xacro:include filename="$(find usf_robot_description)/urdf/usf_robot.gazebo" />
<link name="base_link">
  <inertial>
    <origin xyz="-0.0012975702339316458 0.0002391875259812596 0.07848423930082526" rpy="0 0 0"/>
    <mass value="6.154994198728063"/>
    <inertia ixx="0.019969" iyy="0.019616" izz="0.021212" ixy="-7.9e-05" iyz="0.000169" ixz="-0.00079"/>
  </inertial>
  <visual>
    <origin xyz="0 0 0" rpy="0 0 0"/>
    <geometry>
      <mesh filename="file://$(find usf_robot_description)/meshes/base_link.stl" scale="0.001 0.001 0.001"/>
    </geometry>
    <material name="silver"/>
  </visual>
  <collision>
    <origin xyz="0 0 0" rpy="0 0 0"/>
    <geometry>
      <mesh filename="file://$(find usf_robot_description)/meshes/base_link.stl" scale="0.001 0.001 0.001"/>
    </geometry>
  </collision>
</link>

<link name="lid_1">
  <inertial>
    <origin xyz="-0.06540816100240741 0.012535639612029087 -0.05233892218549853" rpy="0 0 0"/>
    <mass value="0.4948507657185058"/>
    <inertia ixx="0.000881" iyy="0.000749" izz="0.001627" ixy="6e-06" iyz="-3e-06" ixz="2e-06"/>
  </inertial>
  <visual>
    <origin xyz="-0.06 0.010789 -0.054982" rpy="0 0 0"/>
    <geometry>
      <mesh filename="file://$(find usf_robot_description)/meshes/lid_1.stl" scale="0.001 0.001 0.001"/>
    </geometry>
    <material name="silver"/>
  </visual>
  <collision>
    <origin xyz="-0.06 0.010789 -0.054982" rpy="0 0 0"/>
    <geometry>
      <mesh filename="file://$(find usf_robot_description)/meshes/lid_1.stl" scale="0.001 0.001 0.001"/>
    </geometry>
  </collision>
</link>

<link name="ring0_1">
  <inertial>
    <origin xyz="-0.0468408299324239 -0.0008613226907141552 0.009500400471942588" rpy="0 0 0"/>
    <mass value="0.941600081983875"/>
    <inertia ixx="0.000746" iyy="0.00062" izz="0.001309" ixy="0.0" iyz="0.0" ixz="0.0"/>
  </inertial>
  <visual>
    <origin xyz="-0.046436 -0.000258 -0.135403" rpy="0 0 0"/>
    <geometry>
      <mesh filename="file://$(find usf_robot_description)/meshes/ring0_1.stl" scale="0.001 0.001 0.001"/>
    </geometry>
    <material name="silver"/>
  </visual>
  <collision>
    <origin xyz="-0.046436 -0.000258 -0.135403" rpy="0 0 0"/>
    <geometry>
      <mesh filename="file://$(find usf_robot_description)/meshes/ring0_1.stl" scale="0.001 0.001 0.001"/>
    </geometry>
  </collision>
</link>

<link name="ring1_1">
  <inertial>
    <origin xyz="-0.0461589023770708 -0.0006939310506300211 0.011754118172135675" rpy="0 0 0"/>
    <mass value="0.34619607318588386"/>
    <inertia ixx="0.000391" iyy="0.000387" izz="0.000747" ixy="-0.0" iyz="-0.0" ixz="0.0"/>
  </inertial>
  <visual>
    <origin xyz="-0.046436 -0.000258 -0.154403" rpy="0 0 0"/>
    <geometry>
      <mesh filename="file://$(find usf_robot_description)/meshes/ring1_1.stl" scale="0.001 0.001 0.001"/>
    </geometry>
    <material name="silver"/>
  </visual>
  <collision>
    <origin xyz="-0.046436 -0.000258 -0.154403" rpy="0 0 0"/>
    <geometry>
      <mesh filename="file://$(find usf_robot_description)/meshes/ring1_1.stl" scale="0.001 0.001 0.001"/>
    </geometry>
  </collision>
</link>

<link name="link0_1">
  <inertial>
    <origin xyz="-0.0014986562382380856 0.15315746866571897 0.20709242313834803" rpy="0 0 0"/>
    <mass value="1.0538487272888062"/>
    <inertia ixx="0.001388" iyy="0.00107" izz="0.000733" ixy="1e-06" iyz="4.3e-05" ixz="-0.0"/>
  </inertial>
  <visual>
    <origin xyz="-0.001349 0.155012 0.015999" rpy="0 0 0"/>
    <geometry>
      <mesh filename="file://$(find usf_robot_description)/meshes/link0_1.stl" scale="0.001 0.001 0.001"/>
    </geometry>
    <material name="silver"/>
  </visual>
  <collision>
    <origin xyz="-0.001349 0.155012 0.015999" rpy="0 0 0"/>
    <geometry>
      <mesh filename="file://$(find usf_robot_description)/meshes/link0_1.stl" scale="0.001 0.001 0.001"/>
    </geometry>
  </collision>
</link>

<link name="link1_1">
  <inertial>
    <origin xyz="-0.18022565383222433 0.20449287186770243 -0.40527708338796736" rpy="0 0 0"/>
    <mass value="1.186540896033691"/>
    <inertia ixx="0.004183" iyy="0.003256" izz="0.001086" ixy="1e-06" iyz="7.7e-05" ixz="-4e-06"/>
  </inertial>
  <visual>
    <origin xyz="-0.180309 0.206033 -0.699863" rpy="0 0 0"/>
    <geometry>
      <mesh filename="file://$(find usf_robot_description)/meshes/link1_1.stl" scale="0.001 0.001 0.001"/>
    </geometry>
    <material name="silver"/>
  </visual>
  <collision>
    <origin xyz="-0.180309 0.206033 -0.699863" rpy="0 0 0"/>
    <geometry>
      <mesh filename="file://$(find usf_robot_description)/meshes/link1_1.stl" scale="0.001 0.001 0.001"/>
    </geometry>
  </collision>
</link>

<link name="link2_1">
  <inertial>
    <origin xyz="-0.0008902954638643904 0.525964310736137 0.3629950586280912" rpy="0 0 0"/>
    <mass value="0.8748164739188804"/>
    <inertia ixx="0.002814" iyy="0.002099" izz="0.000862" ixy="-0.0" iyz="-3e-06" ixz="5e-06"/>
  </inertial>
  <visual>
    <origin xyz="-0.000595 0.525864 -0.04782" rpy="0 0 0"/>
    <geometry>
      <mesh filename="file://$(find usf_robot_description)/meshes/link2_1.stl" scale="0.001 0.001 0.001"/>
    </geometry>
    <material name="silver"/>
  </visual>
  <collision>
    <origin xyz="-0.000595 0.525864 -0.04782" rpy="0 0 0"/>
    <geometry>
      <mesh filename="file://$(find usf_robot_description)/meshes/link2_1.stl" scale="0.001 0.001 0.001"/>
    </geometry>
  </collision>
</link>

<link name="wrist_1">
  <inertial>
    <origin xyz="-0.0003393814160204296 0.0020883584987778617 0.01439453543485636" rpy="0 0 0"/>
    <mass value="0.21957082315580698"/>
    <inertia ixx="3.2e-05" iyy="8.8e-05" izz="8.9e-05" ixy="0.0" iyz="-6e-06" ixz="1e-06"/>
  </inertial>
  <visual>
    <origin xyz="0.009114 0.000149 -0.483436" rpy="0 0 0"/>
    <geometry>
      <mesh filename="file://$(find usf_robot_description)/meshes/wrist_1.stl" scale="0.001 0.001 0.001"/>
    </geometry>
    <material name="silver"/>
  </visual>
  <collision>
    <origin xyz="0.009114 0.000149 -0.483436" rpy="0 0 0"/>
    <geometry>
      <mesh filename="file://$(find usf_robot_description)/meshes/wrist_1.stl" scale="0.001 0.001 0.001"/>
    </geometry>
  </collision>
</link>

<link name="claw1_1">
  <inertial>
    <origin xyz="-0.02446934404744909 -0.006626193629654924 -0.08228134951175681" rpy="0 0 0"/>
    <mass value="0.07713386767182136"/>
    <inertia ixx="2.2e-05" iyy="3.1e-05" izz="4.3e-05" ixy="-1e-05" iyz="1e-06" ixz="5e-06"/>
  </inertial>
  <visual>
    <origin xyz="0.018915 -0.017152 -0.597441" rpy="0 0 0"/>
    <geometry>
      <mesh filename="file://$(find usf_robot_description)/meshes/claw1_1.stl" scale="0.001 0.001 0.001"/>
    </geometry>
    <material name="silver"/>
  </visual>
  <collision>
    <origin xyz="0.018915 -0.017152 -0.597441" rpy="0 0 0"/>
    <geometry>
      <mesh filename="file://$(find usf_robot_description)/meshes/claw1_1.stl" scale="0.001 0.001 0.001"/>
    </geometry>
  </collision>
</link>

<link name="claw0_1">
  <inertial>
    <origin xyz="0.031293157583235906 -0.01705162122144075 -0.08137112439052674" rpy="0 0 0"/>
    <mass value="0.06093667733333771"/>
    <inertia ixx="1.9e-05" iyy="1.7e-05" izz="2.8e-05" ixy="6e-06" iyz="1e-06" ixz="-4e-06"/>
  </inertial>
  <visual>
    <origin xyz="0.002789 -0.025243 -0.5975" rpy="0 0 0"/>
    <geometry>
      <mesh filename="file://$(find usf_robot_description)/meshes/claw0_1.stl" scale="0.001 0.001 0.001"/>
    </geometry>
    <material name="silver"/>
  </visual>
  <collision>
    <origin xyz="0.002789 -0.025243 -0.5975" rpy="0 0 0"/>
    <geometry>
      <mesh filename="file://$(find usf_robot_description)/meshes/claw0_1.stl" scale="0.001 0.001 0.001"/>
    </geometry>
  </collision>
</link>

<joint name="lid_to_base_link" type="fixed">
  <origin xyz="0.06 -0.010789 0.054982" rpy="0 0 0"/>
  <parent link="base_link"/>
  <child link="lid_1"/>
</joint>

<joint name="ring0_to_base_link" type="fixed">
  <origin xyz="0.046436 0.000258 0.135403" rpy="0 0 0"/>
  <parent link="base_link"/>
  <child link="ring0_1"/>
</joint>

<joint name="ring1_to_ring0" type="fixed">
  <origin xyz="0.0 0.0 0.019" rpy="0 0 0"/>
  <parent link="ring0_1"/>
  <child link="ring1_1"/>
</joint>

<joint name="link0_to_base_link" type="continuous">
  <origin xyz="0.001349 -0.155012 -0.015999" rpy="0 0 0"/>
  <parent link="base_link"/>
  <child link="link0_1"/>
  <axis xyz="0.0 0.0 1.0"/>
</joint>

<joint name="link1_to_link0" type="revolute">
  <origin xyz="0.17896 -0.051021 0.715862" rpy="0 0 0"/>
  <parent link="link0_1"/>
  <child link="link1_1"/>
  <axis xyz="0.0 -1.0 0.0"/>
  <limit upper="2.356194" lower="-1.570796" effort="100" velocity="100"/>
</joint>

<joint name="link2_to_link1" type="revolute">
  <origin xyz="-0.179714 -0.319831 -0.652043" rpy="0 0 0"/>
  <parent link="link1_1"/>
  <child link="link2_1"/>
  <axis xyz="-0.0 -1.0 0.0"/>
  <limit upper="2.356194" lower="-1.570796" effort="100" velocity="100"/>
</joint>

<joint name="wrist_to_link2" type="revolute">
  <origin xyz="-0.009709 0.525715 0.435616" rpy="0 0 0"/>
  <parent link="link2_1"/>
  <child link="wrist_1"/>
  <axis xyz="-0.0 0.0 1.0"/>
  <limit upper="4.712389" lower="0.0" effort="100" velocity="100"/>
</joint>

<joint name="claw1_to_wrist" type="revolute">
  <origin xyz="-0.009801 0.017301 0.114005" rpy="0 0 0"/>
  <parent link="wrist_1"/>
  <child link="claw1_1"/>
  <axis xyz="-0.0 1.0 -0.0"/>
  <limit upper="1.134464" lower="-0.261799" effort="100" velocity="100"/>
</joint>

<joint name="claw0_to_wrist" type="revolute">
  <origin xyz="0.006325 0.025392 0.114064" rpy="0 0 0"/>
  <parent link="wrist_1"/>
  <child link="claw0_1"/>
  <axis xyz="0.0 -1.0 -0.0"/>
  <limit upper="1.134464" lower="-0.261799" effort="100" velocity="100"/>
</joint>

</robot>
