<?xml version="1.0" ?>
<!-- =================================================================================== -->
<!-- |    This document was autogenerated by xacro from usf_robot.xacro                | -->
<!-- |    EDITING THIS FILE BY HAND IS NOT RECOMMENDED                                 | -->
<!-- =================================================================================== -->
<robot name="usf_robot">
  <!-- USF colors -->
  <material name="gold">
    <color rgba="0.721 0.525 0.043 1.0"/>
  </material>
  <material name="dark_evergreen">
    <color rgba="0.0 0.392 0.0 1.0"/>
  </material>
  <material name="silver">
    <color rgba="0.700 0.700 0.700 1.000"/>
  </material>
  <transmission name="link0_to_base_link_tran">
    <type>transmission_interface/SimpleTransmission</type>
    <joint name="link0_to_base_link">
      <hardwareInterface>hardware_interface/EffortJointInterface</hardwareInterface>
    </joint>
    <actuator name="link0_to_base_link_actr">
      <hardwareInterface>hardware_interface/EffortJointInterface</hardwareInterface>
      <mechanicalReduction>1</mechanicalReduction>
    </actuator>
  </transmission>
  <transmission name="link1_to_link0_tran">
    <type>transmission_interface/SimpleTransmission</type>
    <joint name="link1_to_link0">
      <hardwareInterface>hardware_interface/EffortJointInterface</hardwareInterface>
    </joint>
    <actuator name="link1_to_link0_actr">
      <hardwareInterface>hardware_interface/EffortJointInterface</hardwareInterface>
      <mechanicalReduction>1</mechanicalReduction>
    </actuator>
  </transmission>
  <transmission name="link2_to_link1_tran">
    <type>transmission_interface/SimpleTransmission</type>
    <joint name="link2_to_link1">
      <hardwareInterface>hardware_interface/EffortJointInterface</hardwareInterface>
    </joint>
    <actuator name="link2_to_link1_actr">
      <hardwareInterface>hardware_interface/EffortJointInterface</hardwareInterface>
      <mechanicalReduction>1</mechanicalReduction>
    </actuator>
  </transmission>
  <transmission name="wrist_to_link2_tran">
    <type>transmission_interface/SimpleTransmission</type>
    <joint name="wrist_to_link2">
      <hardwareInterface>hardware_interface/EffortJointInterface</hardwareInterface>
    </joint>
    <actuator name="wrist_to_link2_actr">
      <hardwareInterface>hardware_interface/EffortJointInterface</hardwareInterface>
      <mechanicalReduction>1</mechanicalReduction>
    </actuator>
  </transmission>
  <transmission name="claw0_to_wrist_tran">
    <type>transmission_interface/SimpleTransmission</type>
    <joint name="claw0_to_wrist">
      <hardwareInterface>hardware_interface/EffortJointInterface</hardwareInterface>
    </joint>
    <actuator name="claw0_to_wrist_actr">
      <hardwareInterface>hardware_interface/EffortJointInterface</hardwareInterface>
      <mechanicalReduction>1</mechanicalReduction>
    </actuator>
  </transmission>
  <transmission name="claw1_to_wrist_tran">
    <type>transmission_interface/SimpleTransmission</type>
    <joint name="claw1_to_wrist">
      <hardwareInterface>hardware_interface/EffortJointInterface</hardwareInterface>
    </joint>
    <actuator name="claw1_to_wrist_actr">
      <hardwareInterface>hardware_interface/EffortJointInterface</hardwareInterface>
      <mechanicalReduction>1</mechanicalReduction>
    </actuator>
  </transmission>
  <gazebo>
    <plugin filename="libgazebo_ros_control.so" name="control"/>
  </gazebo>
  <gazebo reference="base_link">
    <material>Gazebo/Silver</material>
    <mu1>0.2</mu1>
    <mu2>0.2</mu2>
    <self_collide>true</self_collide>
    <gravity>true</gravity>
  </gazebo>
  <gazebo reference="link0_1">
    <material>Gazebo/Silver</material>
    <mu1>0.2</mu1>
    <mu2>0.2</mu2>
    <self_collide>true</self_collide>
  </gazebo>
  <gazebo reference="link1_1">
    <material>Gazebo/Silver</material>
    <mu1>0.2</mu1>
    <mu2>0.2</mu2>
    <self_collide>true</self_collide>
  </gazebo>
  <gazebo reference="link2_1">
    <material>Gazebo/Silver</material>
    <mu1>0.2</mu1>
    <mu2>0.2</mu2>
    <self_collide>true</self_collide>
  </gazebo>
  <gazebo reference="wrist_1">
    <material>Gazebo/Silver</material>
    <mu1>0.2</mu1>
    <mu2>0.2</mu2>
    <self_collide>true</self_collide>
  </gazebo>
  <gazebo reference="claw0_1">
    <material>Gazebo/Silver</material>
    <mu1>0.2</mu1>
    <mu2>0.2</mu2>
    <self_collide>true</self_collide>
  </gazebo>
  <gazebo reference="claw1_1">
    <material>Gazebo/Silver</material>
    <mu1>0.2</mu1>
    <mu2>0.2</mu2>
    <self_collide>true</self_collide>
  </gazebo>
  <link name="base_link">
    <inertial>
      <origin rpy="0 0 0" xyz="4.095840186019689e-05 -0.00047837113585616297 0.030465846604467023"/>
      <mass value="6.2514798322801415"/>
      <inertia ixx="0.01073" ixy="-0.0" ixz="0.0" iyy="0.010393" iyz="8e-06" izz="0.014172"/>
    </inertial>
    <visual>
      <origin rpy="0 0 0" xyz="0 0 0"/>
      <geometry>
        <mesh filename="file:///home/cyborg/usf_robot_description/install/usf_robot_description/share/usf_robot_description/meshes/base_link.stl" scale="0.001 0.001 0.001"/>
      </geometry>
      <material name="gold"/>
    </visual>
    <collision>
      <origin rpy="0 0 0" xyz="0 0 0"/>
      <geometry>
        <mesh filename="file:///home/cyborg/usf_robot_description/install/usf_robot_description/share/usf_robot_description/meshes/base_link.stl" scale="0.001 0.001 0.001"/>
      </geometry>
    </collision>
  </link>
  <link name="link0_1">
    <inertial>
      <origin rpy="0 0 0" xyz="-2.716259298227874e-06 -0.0010380049259447563 0.024075797292657686"/>
      <mass value="1.1929271090807336"/>
      <inertia ixx="0.001533" ixy="1e-06" ixz="-0.0" iyy="0.001298" iyz="3.9e-05" izz="0.000904"/>
    </inertial>
    <visual>
      <origin rpy="0 0 0" xyz="0.0002 0.000356 -0.07854"/>
      <geometry>
        <mesh filename="file:///home/cyborg/usf_robot_description/install/usf_robot_description/share/usf_robot_description/meshes/link0_1.stl" scale="0.001 0.001 0.001"/>
      </geometry>
      <material name="dark_evergreen"/>
    </visual>
    <collision>
      <origin rpy="0 0 0" xyz="0.0002 0.000356 -0.07854"/>
      <geometry>
        <mesh filename="file:///home/cyborg/usf_robot_description/install/usf_robot_description/share/usf_robot_description/meshes/link0_1.stl" scale="0.001 0.001 0.001"/>
      </geometry>
    </collision>
  </link>
  <link name="link1_1">
    <inertial>
      <origin rpy="0 0 0" xyz="-0.0019587652913026312 0.034488416417771325 0.06565011429736459"/>
      <mass value="1.1661006941164045"/>
      <inertia ixx="0.004129" ixy="1e-06" ixz="-5e-06" iyy="0.003233" iyz="0.000103" izz="0.001055"/>
    </inertial>
    <visual>
      <origin rpy="0 0 0" xyz="-0.003934 0.034413 -0.147151"/>
      <geometry>
        <mesh filename="package://usf_robot_description/meshes/link1_1.stl" scale="0.001 0.001 0.001"/>
      </geometry>
      <material name="dark_evergreen"/>
    </visual>
    <collision>
      <origin rpy="0 0 0" xyz="-0.003934 0.034413 -0.147151"/>
      <geometry>
        <mesh filename="package://usf_robot_description/meshes/link1_1.stl" scale="0.001 0.001 0.001"/>
      </geometry>
    </collision>
  </link>
  <link name="link2_1">
    <inertial>
      <origin rpy="0 0 0" xyz="-0.0006992106483605159 0.034752006278891 0.06238936881043755"/>
      <mass value="1.2752880173767804"/>
      <inertia ixx="0.003526" ixy="1e-06" ixz="-4.8e-05" iyy="0.002718" iyz="4.5e-05" izz="0.001303"/>
    </inertial>
    <visual>
      <origin rpy="0 0 0" xyz="-0.004434 0.033467 -0.275786"/>
      <geometry>
        <mesh filename="package://usf_robot_description/meshes/link2_1.stl" scale="0.001 0.001 0.001"/>
      </geometry>
      <material name="dark_evergreen"/>
    </visual>
    <collision>
      <origin rpy="0 0 0" xyz="-0.004434 0.033467 -0.275786"/>
      <geometry>
        <mesh filename="package://usf_robot_description/meshes/link2_1.stl" scale="0.001 0.001 0.001"/>
      </geometry>
    </collision>
  </link>
  <link name="wrist_1">
    <inertial>
      <origin rpy="0 0 0" xyz="-0.0005413092492828012 0.0012694599894109916 0.01735230955560413"/>
      <mass value="0.27580026748282094"/>
      <inertia ixx="4.6e-05" ixy="1e-06" ixz="1e-06" iyy="0.000102" iyz="-3e-06" izz="9.7e-05"/>
    </inertial>
    <visual>
      <origin rpy="0 0 0" xyz="0.009156 0.000935 -0.40079"/>
      <geometry>
        <mesh filename="file:///home/cyborg/usf_robot_description/install/usf_robot_description/share/usf_robot_description/meshes/wrist_1.stl" scale="0.001 0.001 0.001"/>
      </geometry>
      <material name="dark_evergreen"/>
    </visual>
    <collision>
      <origin rpy="0 0 0" xyz="0.009156 0.000935 -0.40079"/>
      <geometry>
        <mesh filename="file:///home/cyborg/usf_robot_description/install/usf_robot_description/share/usf_robot_description/meshes/wrist_1.stl" scale="0.001 0.001 0.001"/>
      </geometry>
    </collision>
  </link>
  <link name="claw0_1">
    <inertial>
      <origin rpy="0 0 0" xyz="0.029746498963837527 -0.015181296968975237 0.0037018851488843096"/>
      <mass value="0.06042467247708934"/>
      <inertia ixx="1.9e-05" ixy="6e-06" ixz="-4e-06" iyy="1.7e-05" iyz="1e-06" izz="2.8e-05"/>
    </inertial>
    <visual>
      <origin rpy="0 0 0" xyz="0.001497 -0.023737 -0.429729"/>
      <geometry>
        <mesh filename="file:///home/cyborg/usf_robot_description/install/usf_robot_description/share/usf_robot_description/meshes/claw0_1.stl" scale="0.001 0.001 0.001"/>
      </geometry>
      <material name="gold"/>
    </visual>
    <collision>
      <origin rpy="0 0 0" xyz="0.001497 -0.023737 -0.429729"/>
      <geometry>
        <mesh filename="file:///home/cyborg/usf_robot_description/install/usf_robot_description/share/usf_robot_description/meshes/claw0_1.stl" scale="0.001 0.001 0.001"/>
      </geometry>
    </collision>
  </link>
  <link name="claw1_1">
    <inertial>
      <origin rpy="0 0 0" xyz="-0.023394673493672247 -0.004684523309569305 0.00039325660605243895"/>
      <mass value="0.07705542391594017"/>
      <inertia ixx="2.2e-05" ixy="-1e-05" ixz="5e-06" iyy="3.1e-05" iyz="1e-06" izz="4.3e-05"/>
    </inertial>
    <visual>
      <origin rpy="0 0 0" xyz="0.018998 -0.01558 -0.432148"/>
      <geometry>
        <mesh filename="file:///home/cyborg/usf_robot_description/install/usf_robot_description/share/usf_robot_description/meshes/claw1_1.stl" scale="0.001 0.001 0.001"/>
      </geometry>
      <material name="gold"/>
    </visual>
    <collision>
      <origin rpy="0 0 0" xyz="0.018998 -0.01558 -0.432148"/>
      <geometry>
        <mesh filename="file:///home/cyborg/usf_robot_description/install/usf_robot_description/share/usf_robot_description/meshes/claw1_1.stl" scale="0.001 0.001 0.001"/>
      </geometry>
    </collision>
  </link>
  <joint name="link0_to_base_link" type="revolute">
    <origin rpy="0 0 0" xyz="-0.0002 -0.000356 0.07854"/>
    <parent link="base_link"/>
    <child link="link0_1"/>
    <axis xyz="-0.0 0.0 1.0"/>
    <limit effort="100" lower="0.0" upper="4.712389" velocity="100"/>
  </joint>
  <joint name="link1_to_link0" type="revolute">
    <origin rpy="0 0 0" xyz="0.002123 -0.03474 0.069949"/>
    <parent link="link0_1"/>
    <child link="link1_1"/>
    <axis xyz="-0.0 -1.0 -0.0"/>
    <limit effort="100" lower="-1.570796" upper="1.570796" velocity="100"/>
  </joint>
  <joint name="link2_to_link1" type="revolute">
    <origin rpy="0 0 0" xyz="0.0005 0.000946 0.128635"/>
    <parent link="link1_1"/>
    <child link="link2_1"/>
    <axis xyz="0.0 -1.0 -0.0"/>
    <limit effort="100" lower="-1.570796" upper="1.570796" velocity="100"/>
  </joint>
  <joint name="wrist_to_link2" type="revolute">
    <origin rpy="0 0 0" xyz="-0.009567 0.034632 0.128329"/>
    <parent link="link2_1"/>
    <child link="wrist_1"/>
    <axis xyz="-0.0 -0.0 1.0"/>
    <limit effort="100" lower="0.0" upper="4.712389" velocity="100"/>
  </joint>
  <joint name="claw0_to_wrist" type="revolute">
    <origin rpy="0 0 0" xyz="0.007659 0.024672 0.028939"/>
    <parent link="wrist_1"/>
    <child link="claw0_1"/>
    <axis xyz="0.0 1.0 0.0"/>
    <limit effort="100" lower="-1.25" upper="0.0" velocity="100"/>
  </joint>
  <joint name="claw1_to_wrist" type="revolute">
    <origin rpy="0 0 0" xyz="-0.009842 0.016515 0.031358"/>
    <parent link="wrist_1"/>
    <child link="claw1_1"/>
    <axis xyz="0.0 -1.0 0.0"/>
    <limit effort="100" lower="-1.134464" upper="1.25" velocity="100"/>
    <mimic joint="claw0_to_wrist" multiplier="1.0"/>
  </joint>
</robot>
